Workbook

Sheet Readme
A1: Note: Input data has been truncated and slightly altered
A2: If your input data is longer, you may need to adjust the ranges of the formulae to account for that

Sheet Input
A1: Input:
A2: 7 49 29 49 6 92 61 11 6 792 94 296 3976
A3: 485 11 34 53 175 74 95 36 8 643 9 658 391
A4: 3849 693 1 137 624 45 617 47 14 712 6 877 65
A5: 2238 1378 6 152 521 666 989 667 55 488 4 65 22
A6: + + * * + + * * * * + + +

Sheet Part 1
A1: Cleaned up/transposed data: | H1: Part 1:
A2: {=TRANSPOSE(_xlfn.TEXTSPLIT(TRIM(SUBSTITUTE(Input!A2,CHAR(32)," "))," ")*1)} -> 7 | B2: {=TRANSPOSE(_xlfn.TEXTSPLIT(TRIM(SUBSTITUTE(Input!A3,CHAR(32)," "))," ")*1)} -> 485 | C2: {=TRANSPOSE(_xlfn.TEXTSPLIT(TRIM(SUBSTITUTE(Input!A4,CHAR(32)," "))," ")*1)} -> 3849 | D2: {=TRANSPOSE(_xlfn.TEXTSPLIT(TRIM(SUBSTITUTE(Input!A5,CHAR(32)," "))," ")*1)} -> 2238 | E2: {=TRANSPOSE(_xlfn.TEXTSPLIT(TRIM(SUBSTITUTE(Input!A6,CHAR(32)," "))," "))} -> + | F2: =IF(E2="+",SUM(A2:D2),PRODUCT(A2:D2)) -> 6579 | H2: =SUM(F2:F1001) -> 180546791455
A3: 49 | B3: 11 | C3: 693 | D3: 1378 | E3: + | F3: =IF(E3="+",SUM(A3:D3),PRODUCT(A3:D3)) -> 2131
A4: 29 | B4: 34 | C4: 1 | D4: 6 | E4: * | F4: =IF(E4="+",SUM(A4:D4),PRODUCT(A4:D4)) -> 5916
A5: 49 | B5: 53 | C5: 137 | D5: 152 | E5: * | F5: =IF(E5="+",SUM(A5:D5),PRODUCT(A5:D5)) -> 54079928
A6: 6 | B6: 175 | C6: 624 | D6: 521 | E6: + | F6: =IF(E6="+",SUM(A6:D6),PRODUCT(A6:D6)) -> 1326
A7: 92 | B7: 74 | C7: 45 | D7: 666 | E7: + | F7: =IF(E7="+",SUM(A7:D7),PRODUCT(A7:D7)) -> 877
A8: 61 | B8: 95 | C8: 617 | D8: 989 | E8: * | F8: =IF(E8="+",SUM(A8:D8),PRODUCT(A8:D8)) -> 3536184335
A9: 11 | B9: 36 | C9: 47 | D9: 667 | E9: * | F9: =IF(E9="+",SUM(A9:D9),PRODUCT(A9:D9)) -> 12414204
A10: 6 | B10: 8 | C10: 14 | D10: 55 | E10: * | F10: =IF(E10="+",SUM(A10:D10),PRODUCT(A10:D10)) -> 36960
A11: 792 | B11: 643 | C11: 712 | D11: 488 | E11: * | F11: =IF(E11="+",SUM(A11:D11),PRODUCT(A11:D11)) -> 176944052736
A12: 94 | B12: 9 | C12: 6 | D12: 4 | E12: + | F12: =IF(E12="+",SUM(A12:D12),PRODUCT(A12:D12)) -> 113
A13: 296 | B13: 658 | C13: 877 | D13: 65 | E13: + | F13: =IF(E13="+",SUM(A13:D13),PRODUCT(A13:D13)) -> 1896
A14: 3976 | B14: 391 | C14: 65 | D14: 22 | E14: + | F14: =IF(E14="+",SUM(A14:D14),PRODUCT(A14:D14)) -> 4454
F15: =IF(E15="+",SUM(A15:D15),PRODUCT(A15:D15)) -> 0
F16: =IF(E16="+",SUM(A16:D16),PRODUCT(A16:D16)) -> 0
F17: =IF(E17="+",SUM(A17:D17),PRODUCT(A17:D17)) -> 0
F18: =IF(E18="+",SUM(A18:D18),PRODUCT(A18:D18)) -> 0
F19: =IF(E19="+",SUM(A19:D19),PRODUCT(A19:D19)) -> 0
F20: =IF(E20="+",SUM(A20:D20),PRODUCT(A20:D20)) -> 0
F21: =IF(E21="+",SUM(A21:D21),PRODUCT(A21:D21)) -> 0
F22: =IF(E22="+",SUM(A22:D22),PRODUCT(A22:D22)) -> 0
F23: =IF(E23="+",SUM(A23:D23),PRODUCT(A23:D23)) -> 0
F24: =IF(E24="+",SUM(A24:D24),PRODUCT(A24:D24)) -> 0
F25: =IF(E25="+",SUM(A25:D25),PRODUCT(A25:D25)) -> 0
F26: =IF(E26="+",SUM(A26:D26),PRODUCT(A26:D26)) -> 0
... F1001: =IF(E1001="+",SUM(A1001:D1001),PRODUCT(A1001:D1001)) -> 0

Sheet Part 2
A1: Parsed/transposed data: | K1: Part 2:
A2: {=TRANSPOSE(TRANSPOSE(MID(Input!A2,_xlfn.SEQUENCE(LEN(Input!A2)),1)))} -> 7 | B2: {=TRANSPOSE(TRANSPOSE(MID(Input!A3,_xlfn.SEQUENCE(LEN(Input!A3)),1)))} -> 4 | C2: {=TRANSPOSE(TRANSPOSE(MID(Input!A4,_xlfn.SEQUENCE(LEN(Input!A4)),1)))} -> 3 | D2: {=TRANSPOSE(TRANSPOSE(MID(Input!A5,_xlfn.SEQUENCE(LEN(Input!A5)),1)))} -> 2 | E2: {=TRANSPOSE(TRANSPOSE(MID(Input!A6,_xlfn.SEQUENCE(LEN(Input!A6)),1)))} -> + | F2: {=_xlfn.BYROW(A2:D3748,_xlfn.LAMBDA(_xlpm.r,_xlfn.TEXTJOIN("",TRUE,_xlpm.r)))} -> 7432 | G2: {=TRANSPOSE(_xlfn.TEXTSPLIT(_xlfn.ARRAYTOTEXT(_xlfn.TEXTJOIN(",",FALSE,TRIM(_xlfn.ANCHORARRAY(F2)))),",,",FALSE))} -> 7432,882,543,98 | H2: {=_xlfn._xlws.FILTER(_xlfn.ANCHORARRAY(E2),(_xlfn.ANCHORARRAY(E2)="+")+(_xlfn.ANCHORARRAY(E2)="*"),"")} -> + | I2: {=IF(G2<>"",_xlfn.LET(_xlpm.num,_xlfn.TEXTSPLIT(G2,",")*1,IF(H2="+",SUM(_xlpm.num),PRODUCT(_xlpm.num))),"")} -> 8955 | K2: =SUM(I2:I3748) -> 172053045250
B3: 8 | C3: 8 | D3: 2 | F3: 882 | G3: 1,63,4197,9138 | H3: + | I3: {=IF(G3<>"",_xlfn.LET(_xlpm.num,_xlfn.TEXTSPLIT(G3,",")*1,IF(H3="+",SUM(_xlpm.num),PRODUCT(_xlpm.num))),"")} -> 13399
B4: 5 | C4: 4 | D4: 3 | F4: 543 | G4: 23,9416 | H4: * | I4: {=IF(G4<>"",_xlfn.LET(_xlpm.num,_xlfn.TEXTSPLIT(G4,",")*1,IF(H4="+",SUM(_xlpm.num),PRODUCT(_xlpm.num))),"")} -> 216568
C5: 9 | D5: 8 | F5: 98 | G5: 4511,9335,72 | H5: * | I5: {=IF(G5<>"",_xlfn.LET(_xlpm.num,_xlfn.TEXTSPLIT(G5,",")*1,IF(H5="+",SUM(_xlpm.num),PRODUCT(_xlpm.num))),"")} -> 3031933320
G6: 6165,722,541 | H6: + | I6: {=IF(G6<>"",_xlfn.LET(_xlpm.num,_xlfn.TEXTSPLIT(G6,",")*1,IF(H6="+",SUM(_xlpm.num),PRODUCT(_xlpm.num))),"")} -> 7428
D7: 1 | E7: + | F7: 1 | G7: 6,9746,2456 | H7: + | I7: {=IF(G7<>"",_xlfn.LET(_xlpm.num,_xlfn.TEXTSPLIT(G7,",")*1,IF(H7="+",SUM(_xlpm.num),PRODUCT(_xlpm.num))),"")} -> 12208
C8: 6 | D8: 3 | F8: 63 | G8: 69,6918,1579 | H8: * | I8: {=IF(G8<>"",_xlfn.LET(_xlpm.num,_xlfn.TEXTSPLIT(G8,",")*1,IF(H8="+",SUM(_xlpm.num),PRODUCT(_xlpm.num))),"")} -> 753723018
A9: 4 | B9: 1 | C9: 9 | D9: 7 | F9: 4197 | G9: 6,1346,1677 | H9: * | I9: {=IF(G9<>"",_xlfn.LET(_xlpm.num,_xlfn.TEXTSPLIT(G9,",")*1,IF(H9="+",SUM(_xlpm.num),PRODUCT(_xlpm.num))),"")} -> 13543452
A10: 9 | B10: 1 | C10: 3 | D10: 8 | F10: 9138 | G10: 6815,45 | H10: * | I10: {=IF(G10<>"",_xlfn.LET(_xlpm.num,_xlfn.TEXTSPLIT(G10,",")*1,IF(H10="+",SUM(_xlpm.num),PRODUCT(_xlpm.num))),"")} -> 306675
G11: 7674,9418,2328 | H11: * | I11: {=IF(G11<>"",_xlfn.LET(_xlpm.num,_xlfn.TEXTSPLIT(G11,",")*1,IF(H11="+",SUM(_xlpm.num),PRODUCT(_xlpm.num))),"")} -> 168253248096
A12: 2 | B12: 3 | E12: * | F12: 23 | G12: 9,4964 | H12: + | I12: {=IF(G12<>"",_xlfn.LET(_xlpm.num,_xlfn.TEXTSPLIT(G12,",")*1,IF(H12="+",SUM(_xlpm.num),PRODUCT(_xlpm.num))),"")} -> 4973
A13: 9 | B13: 4 | C13: 1 | D13: 6 | F13: 9416 | G13: 2686,9575,687 | H13: + | I13: {=IF(G13<>"",_xlfn.LET(_xlpm.num,_xlfn.TEXTSPLIT(G13,",")*1,IF(H13="+",SUM(_xlpm.num),PRODUCT(_xlpm.num))),"")} -> 12948
G14: 3,93,7962,6152 | H14: + | I14: {=IF(G14<>"",_xlfn.LET(_xlpm.num,_xlfn.TEXTSPLIT(G14,",")*1,IF(H14="+",SUM(_xlpm.num),PRODUCT(_xlpm.num))),"")} -> 14210
A15: 4 | B15: 5 | C15: 1 | D15: 1 | E15: * | F15: 4511 | I15: {=IF(G15<>"",_xlfn.LET(_xlpm.num,_xlfn.TEXTSPLIT(G15,",")*1,IF(H15="+",SUM(_xlpm.num),PRODUCT(_xlpm.num))),"")}
A16: 9 | B16: 3 | C16: 3 | D16: 5 | F16: 9335 | I16: {=IF(G16<>"",_xlfn.LET(_xlpm.num,_xlfn.TEXTSPLIT(G16,",")*1,IF(H16="+",SUM(_xlpm.num),PRODUCT(_xlpm.num))),"")}
C17: 7 | D17: 2 | F17: 72 | I17: {=IF(G17<>"",_xlfn.LET(_xlpm.num,_xlfn.TEXTSPLIT(G17,",")*1,IF(H17="+",SUM(_xlpm.num),PRODUCT(_xlpm.num))),"")}
I18: {=IF(G18<>"",_xlfn.LET(_xlpm.num,_xlfn.TEXTSPLIT(G18,",")*1,IF(H18="+",SUM(_xlpm.num),PRODUCT(_xlpm.num))),"")}
A19: 6 | B19: 1 | C19: 6 | D19: 5 | E19: + | F19: 6165 | I19: {=IF(G19<>"",_xlfn.LET(_xlpm.num,_xlfn.TEXTSPLIT(G19,",")*1,IF(H19="+",SUM(_xlpm.num),PRODUCT(_xlpm.num))),"")}
B20: 7 | C20: 2 | D20: 2 | F20: 722 | I20: {=IF(G20<>"",_xlfn.LET(_xlpm.num,_xlfn.TEXTSPLIT(G20,",")*1,IF(H20="+",SUM(_xlpm.num),PRODUCT(_xlpm.num))),"")}
B21: 5 | C21: 4 | D21: 1 | F21: 541 | I21: {=IF(G21<>"",_xlfn.LET(_xlpm.num,_xlfn.TEXTSPLIT(G21,",")*1,IF(H21="+",SUM(_xlpm.num),PRODUCT(_xlpm.num))),"")}
I22: {=IF(G22<>"",_xlfn.LET(_xlpm.num,_xlfn.TEXTSPLIT(G22,",")*1,IF(H22="+",SUM(_xlpm.num),PRODUCT(_xlpm.num))),"")}
D23: 6 | E23: + | F23: 6 | I23: {=IF(G23<>"",_xlfn.LET(_xlpm.num,_xlfn.TEXTSPLIT(G23,",")*1,IF(H23="+",SUM(_xlpm.num),PRODUCT(_xlpm.num))),"")}
A24: 9 | B24: 7 | C24: 4 | D24: 6 | F24: 9746 | I24: {=IF(G24<>"",_xlfn.LET(_xlpm.num,_xlfn.TEXTSPLIT(G24,",")*1,IF(H24="+",SUM(_xlpm.num),PRODUCT(_xlpm.num))),"")}
A25: 2 | B25: 4 | C25: 5 | D25: 6 | F25: 2456 | I25: {=IF(G25<>"",_xlfn.LET(_xlpm.num,_xlfn.TEXTSPLIT(G25,",")*1,IF(H25="+",SUM(_xlpm.num),PRODUCT(_xlpm.num))),"")}
I26: {=IF(G26<>"",_xlfn.LET(_xlpm.num,_xlfn.TEXTSPLIT(G26,",")*1,IF(H26="+",SUM(_xlpm.num),PRODUCT(_xlpm.num))),"")}
C27: 6 | D27: 9 | E27: * | F27: 69 | I27: {=IF(G27<>"",_xlfn.LET(_xlpm.num,_xlfn.TEXTSPLIT(G27,",")*1,IF(H27="+",SUM(_xlpm.num),PRODUCT(_xlpm.num))),"")}
A28: 6 | B28: 9 | C28: 1 | D28: 8 | F28: 6918 | I28: {=IF(G28<>"",_xlfn.LET(_xlpm.num,_xlfn.TEXTSPLIT(G28,",")*1,IF(H28="+",SUM(_xlpm.num),PRODUCT(_xlpm.num))),"")}
A29: 1 | B29: 5 | C29: 7 | D29: 9 | F29: 1579 | I29: {=IF(G29<>"",_xlfn.LET(_xlpm.num,_xlfn.TEXTSPLIT(G29,",")*1,IF(H29="+",SUM(_xlpm.num),PRODUCT(_xlpm.num))),"")}
I30: {=IF(G30<>"",_xlfn.LET(_xlpm.num,_xlfn.TEXTSPLIT(G30,",")*1,IF(H30="+",SUM(_xlpm.num),PRODUCT(_xlpm.num))),"")}
D31: 6 | E31: * | F31: 6 | I31: {=IF(G31<>"",_xlfn.LET(_xlpm.num,_xlfn.TEXTSPLIT(G31,",")*1,IF(H31="+",SUM(_xlpm.num),PRODUCT(_xlpm.num))),"")}
A32: 1 | B32: 3 | C32: 4 | D32: 6 | F32: 1346 | I32: {=IF(G32<>"",_xlfn.LET(_xlpm.num,_xlfn.TEXTSPLIT(G32,",")*1,IF(H32="+",SUM(_xlpm.num),PRODUCT(_xlpm.num))),"")}
A33: 1 | B33: 6 | C33: 7 | D33: 7 | F33: 1677 | I33: {=IF(G33<>"",_xlfn.LET(_xlpm.num,_xlfn.TEXTSPLIT(G33,",")*1,IF(H33="+",SUM(_xlpm.num),PRODUCT(_xlpm.num))),"")}
I34: {=IF(G34<>"",_xlfn.LET(_xlpm.num,_xlfn.TEXTSPLIT(G34,",")*1,IF(H34="+",SUM(_xlpm.num),PRODUCT(_xlpm.num))),"")}
A35: 6 | B35: 8 | C35: 1 | D35: 5 | E35: * | F35: 6815 | I35: {=IF(G35<>"",_xlfn.LET(_xlpm.num,_xlfn.TEXTSPLIT(G35,",")*1,IF(H35="+",SUM(_xlpm.num),PRODUCT(_xlpm.num))),"")}
C36: 4 | D36: 5 | F36: 45 | I36: {=IF(G36<>"",_xlfn.LET(_xlpm.num,_xlfn.TEXTSPLIT(G36,",")*1,IF(H36="+",SUM(_xlpm.num),PRODUCT(_xlpm.num))),"")}
I37: {=IF(G37<>"",_xlfn.LET(_xlpm.num,_xlfn.TEXTSPLIT(G37,",")*1,IF(H37="+",SUM(_xlpm.num),PRODUCT(_xlpm.num))),"")}
A38: 7 | B38: 6 | C38: 7 | D38: 4 | E38: * | F38: 7674 | I38: {=IF(G38<>"",_xlfn.LET(_xlpm.num,_xlfn.TEXTSPLIT(G38,",")*1,IF(H38="+",SUM(_xlpm.num),PRODUCT(_xlpm.num))),"")}
A39: 9 | B39: 4 | C39: 1 | D39: 8 | F39: 9418 | I39: {=IF(G39<>"",_xlfn.LET(_xlpm.num,_xlfn.TEXTSPLIT(G39,",")*1,IF(H39="+",SUM(_xlpm.num),PRODUCT(_xlpm.num))),"")}
A40: 2 | B40: 3 | C40: 2 | D40: 8 | F40: 2328 | I40: {=IF(G40<>"",_xlfn.LET(_xlpm.num,_xlfn.TEXTSPLIT(G40,",")*1,IF(H40="+",SUM(_xlpm.num),PRODUCT(_xlpm.num))),"")}
...
